<?xml version="1.0" ?>
<robot name="panda" xmlns:xacro="http://www.ros.org/wiki/xacro">

  <!-- ========================== -->
  <!--     固定底座到世界坐标系     -->
  <!-- ========================== -->
  <link name="world"/>
  <joint name="world_joint" type="fixed">
    <parent link="world"/>
    <child link="panda_link0"/>
    <origin xyz="0 0 0" rpy="0 0 0"/>
  </joint>

  <!-- ========================== -->
  <!--         Panda 链节          -->
  <!-- ========================== -->
  <link name="panda_link0">
    <visual>
      <geometry>
        <mesh filename="package://moveit_resources_panda_description/meshes/visual/link0.dae"/>
      </geometry>
    </visual>
    <collision>
      <geometry>
        <mesh filename="package://moveit_resources_panda_description/meshes/collision/link0.stl"/>
      </geometry>
    </collision>
  </link>

  <link name="panda_link1">
    <visual>
      <geometry>
        <mesh filename="package://moveit_resources_panda_description/meshes/visual/link1.dae"/>
      </geometry>
    </visual>
    <collision>
      <geometry>
        <mesh filename="package://moveit_resources_panda_description/meshes/collision/link1.stl"/>
      </geometry>
    </collision>
  </link>

  <joint name="panda_joint1" type="revolute">
    <parent link="panda_link0"/>
    <child link="panda_link1"/>
    <origin xyz="0 0 0.333" rpy="0 0 0"/>
    <axis xyz="0 0 1"/>
    <limit effort="87" lower="-2.9671" upper="2.9671" velocity="2.3925"/>
  </joint>

  <link name="panda_link2">
    <visual>
      <geometry>
        <mesh filename="package://moveit_resources_panda_description/meshes/visual/link2.dae"/>
      </geometry>
    </visual>
    <collision>
      <geometry>
        <mesh filename="package://moveit_resources_panda_description/meshes/collision/link2.stl"/>
      </geometry>
    </collision>
  </link>

  <joint name="panda_joint2" type="revolute">
    <parent link="panda_link1"/>
    <child link="panda_link2"/>
    <origin xyz="0 0 0" rpy="-1.57079632679 0 0"/>
    <axis xyz="0 0 1"/>
    <limit effort="87" lower="-1.8326" upper="1.8326" velocity="2.3925"/>
  </joint>

  <link name="panda_link3">
    <visual>
      <geometry>
        <mesh filename="package://moveit_resources_panda_description/meshes/visual/link3.dae"/>
      </geometry>
    </visual>
    <collision>
      <geometry>
        <mesh filename="package://moveit_resources_panda_description/meshes/collision/link3.stl"/>
      </geometry>
    </collision>
  </link>

  <joint name="panda_joint3" type="revolute">
    <parent link="panda_link2"/>
    <child link="panda_link3"/>
    <origin xyz="0 -0.316 0" rpy="1.57079632679 0 0"/>
    <axis xyz="0 0 1"/>
    <limit effort="87" lower="-2.9671" upper="2.9671" velocity="2.3925"/>
  </joint>

  <link name="panda_link4">
    <visual>
      <geometry>
        <mesh filename="package://moveit_resources_panda_description/meshes/visual/link4.dae"/>
      </geometry>
    </visual>
    <collision>
      <geometry>
        <mesh filename="package://moveit_resources_panda_description/meshes/collision/link4.stl"/>
      </geometry>
    </collision>
  </link>

  <joint name="panda_joint4" type="revolute">
    <parent link="panda_link3"/>
    <child link="panda_link4"/>
    <origin xyz="0.0825 0 0" rpy="1.57079632679 0 0"/>
    <axis xyz="0 0 1"/>
    <limit effort="87" lower="-3.1416" upper="0.0873" velocity="2.3925"/>
  </joint>

  <link name="panda_link5">
    <visual>
      <geometry>
        <mesh filename="package://moveit_resources_panda_description/meshes/visual/link5.dae"/>
      </geometry>
    </visual>
    <collision>
      <geometry>
        <mesh filename="package://moveit_resources_panda_description/meshes/collision/link5.stl"/>
      </geometry>
    </collision>
  </link>

  <joint name="panda_joint5" type="revolute">
    <parent link="panda_link4"/>
    <child link="panda_link5"/>
    <origin xyz="-0.0825 0.384 0" rpy="-1.57079632679 0 0"/>
    <axis xyz="0 0 1"/>
    <limit effort="12" lower="-2.9671" upper="2.9671" velocity="2.8710"/>
  </joint>

  <link name="panda_link6">
    <visual>
      <geometry>
        <mesh filename="package://moveit_resources_panda_description/meshes/visual/link6.dae"/>
      </geometry>
    </visual>
    <collision>
      <geometry>
        <mesh filename="package://moveit_resources_panda_description/meshes/collision/link6.stl"/>
      </geometry>
    </collision>
  </link>

  <joint name="panda_joint6" type="revolute">
    <parent link="panda_link5"/>
    <child link="panda_link6"/>
    <origin xyz="0 0 0" rpy="1.57079632679 0 0"/>
    <axis xyz="0 0 1"/>
    <limit effort="12" lower="-0.0873" upper="3.8223" velocity="2.8710"/>
  </joint>

  <link name="panda_link7">
    <visual>
      <geometry>
        <mesh filename="package://moveit_resources_panda_description/meshes/visual/link7.dae"/>
      </geometry>
    </visual>
    <collision>
      <geometry>
        <mesh filename="package://moveit_resources_panda_description/meshes/collision/link7.stl"/>
      </geometry>
    </collision>
  </link>

  <joint name="panda_joint7" type="revolute">
    <parent link="panda_link6"/>
    <child link="panda_link7"/>
    <origin xyz="0.088 0 0" rpy="1.57079632679 0 0"/>
    <axis xyz="0 0 1"/>
    <limit effort="12" lower="-2.9671" upper="2.9671" velocity="2.8710"/>
  </joint>

  <!-- 手爪 -->
  <link name="panda_hand">
    <visual>
      <geometry>
        <mesh filename="package://moveit_resources_panda_description/meshes/visual/hand.dae"/>
      </geometry>
    </visual>
    <collision>
      <geometry>
        <mesh filename="package://moveit_resources_panda_description/meshes/collision/hand.stl"/>
      </geometry>
    </collision>
  </link>

  <joint name="panda_hand_joint" type="fixed">
    <parent link="panda_link7"/>
    <child link="panda_hand"/>
    <origin xyz="0 0 0.107" rpy="0 0 -0.785398163397"/>
  </joint>

  <!-- 手指 -->
  <link name="panda_leftfinger">
    <visual>
      <geometry>
        <mesh filename="package://moveit_resources_panda_description/meshes/visual/finger.dae"/>
      </geometry>
    </visual>
    <collision>
      <geometry>
        <mesh filename="package://moveit_resources_panda_description/meshes/collision/finger.stl"/>
      </geometry>
    </collision>
  </link>

  <link name="panda_rightfinger">
    <visual>
      <origin xyz="0 0 0" rpy="0 0 3.14159265359"/>
      <geometry>
        <mesh filename="package://moveit_resources_panda_description/meshes/visual/finger.dae"/>
      </geometry>
    </visual>
    <collision>
      <origin xyz="0 0 0" rpy="0 0 3.14159265359"/>
      <geometry>
        <mesh filename="package://moveit_resources_panda_description/meshes/collision/finger.stl"/>
      </geometry>
    </collision>
  </link>

  <joint name="panda_finger_joint1" type="prismatic">
    <parent link="panda_hand"/>
    <child link="panda_leftfinger"/>
    <origin xyz="0 0 0.0584" rpy="0 0 0"/>
    <axis xyz="0 1 0"/>
    <limit effort="20" lower="0.0" upper="0.04" velocity="0.2"/>
  </joint>

  <joint name="panda_finger_joint2" type="prismatic">
    <parent link="panda_hand"/>
    <child link="panda_rightfinger"/>
    <origin xyz="0 0 0.0584" rpy="0 0 0"/>
    <axis xyz="0 -1 0"/>
    <limit effort="20" lower="0.0" upper="0.04" velocity="0.2"/>
  </joint>

  <!-- ========================== -->
  <!--   ROS2 Control (ros_gz)插件   -->
  <!-- ========================== -->
  <gazebo>
    <plugin name="gz_ros2_control" filename="libgz_ros2_control-system.so">
      <ros>
        <namespace>/panda</namespace>
      </ros>
      <robot_sim_type>gz_ros2_control/GazeboSystem</robot_sim_type>
    </plugin>
  </gazebo>

  <!-- ✅ 固定底座防止坠落 -->
  <gazebo reference="panda_link0">
    <static>true</static>
    <gravity>false</gravity>
  </gazebo>

</robot>
