<?xml version="1.0" ?>
<robot name="panda" xmlns:xacro="http://www.ros.org/wiki/xacro">

  <!-- ========================== -->
  <!--     固定底座到世界坐标系     -->
  <!-- ========================== -->
  <link name="world"/>
  <joint name="world_joint" type="fixed">
    <parent link="world"/>
    <child link="panda_link0"/>
    <origin xyz="0 0 0" rpy="0 0 0"/>
  </joint>

  <!-- ========================== -->
  <!--         Panda 链节          -->
  <!-- ========================== -->
  <link name="panda_link0">
    <inertial>
      <mass value="2.0"/>
      <inertia ixx="0.01" ixy="0.0" ixz="0.0" iyy="0.01" iyz="0.0" izz="0.01"/>
    </inertial>
    <visual>
      <geometry>
        <mesh filename="package://moveit_resources_panda_description/meshes/visual/link0.dae"/>
      </geometry>
    </visual>
    <collision>
      <geometry>
        <mesh filename="package://moveit_resources_panda_description/meshes/collision/link0.stl"/>
      </geometry>
    </collision>
  </link>

  <link name="panda_link1">
    <inertial>
      <mass value="1.5"/>
      <inertia ixx="0.008" ixy="0.0" ixz="0.0" iyy="0.008" iyz="0.0" izz="0.008"/>
    </inertial>
    <visual>
      <geometry>
        <mesh filename="package://moveit_resources_panda_description/meshes/visual/link1.dae"/>
      </geometry>
    </visual>
    <collision>
      <geometry>
        <mesh filename="package://moveit_resources_panda_description/meshes/collision/link1.stl"/>
      </geometry>
    </collision>
  </link>

  <joint name="panda_joint1" type="revolute">
    <parent link="panda_link0"/>
    <child link="panda_link1"/>
    <origin xyz="0 0 0.333" rpy="0 0 0"/>
    <axis xyz="0 0 1"/>
    <limit effort="87" lower="-2.9671" upper="2.9671" velocity="2.3925"/>
  </joint>

  <link name="panda_link2">
    <inertial>
      <mass value="1.5"/>
      <inertia ixx="0.008" ixy="0.0" ixz="0.0" iyy="0.008" iyz="0.0" izz="0.008"/>
    </inertial>
    <visual>
      <geometry>
        <mesh filename="package://moveit_resources_panda_description/meshes/visual/link2.dae"/>
      </geometry>
    </visual>
    <collision>
      <geometry>
        <mesh filename="package://moveit_resources_panda_description/meshes/collision/link2.stl"/>
      </geometry>
    </collision>
  </link>

  <joint name="panda_joint2" type="revolute">
    <parent link="panda_link1"/>
    <child link="panda_link2"/>
    <origin xyz="0 0 0" rpy="-1.57079632679 0 0"/>
    <axis xyz="0 0 1"/>
    <limit effort="87" lower="-1.8326" upper="1.8326" velocity="2.3925"/>
  </joint>

  <link name="panda_link3">
    <inertial>
      <mass value="1.5"/>
      <inertia ixx="0.008" ixy="0.0" ixz="0.0" iyy="0.008" iyz="0.0" izz="0.008"/>
    </inertial>
    <visual>
      <geometry>
        <mesh filename="package://moveit_resources_panda_description/meshes/visual/link3.dae"/>
      </geometry>
    </visual>
    <collision>
      <geometry>
        <mesh filename="package://moveit_resources_panda_description/meshes/collision/link3.stl"/>
      </geometry>
    </collision>
  </link>

  <joint name="panda_joint3" type="revolute">
    <parent link="panda_link2"/>
    <child link="panda_link3"/>
    <origin xyz="0 -0.316 0" rpy="1.57079632679 0 0"/>
    <axis xyz="0 0 1"/>
    <limit effort="87" lower="-2.9671" upper="2.9671" velocity="2.3925"/>
  </joint>

  <link name="panda_link4">
    <inertial>
      <mass value="1.2"/>
      <inertia ixx="0.006" ixy="0.0" ixz="0.0" iyy="0.006" iyz="0.0" izz="0.006"/>
    </inertial>
    <visual>
      <geometry>
        <mesh filename="package://moveit_resources_panda_description/meshes/visual/link4.dae"/>
      </geometry>
    </visual>
    <collision>
      <geometry>
        <mesh filename="package://moveit_resources_panda_description/meshes/collision/link4.stl"/>
      </geometry>
    </collision>
  </link>

  <joint name="panda_joint4" type="revolute">
    <parent link="panda_link3"/>
    <child link="panda_link4"/>
    <origin xyz="0.0825 0 0" rpy="1.57079632679 0 0"/>
    <axis xyz="0 0 1"/>
    <limit effort="87" lower="-3.1416" upper="0.0873" velocity="2.3925"/>
  </joint>

  <link name="panda_link5">
    <inertial>
      <mass value="1.2"/>
      <inertia ixx="0.006" ixy="0.0" ixz="0.0" iyy="0.006" iyz="0.0" izz="0.006"/>
    </inertial>
    <visual>
      <geometry>
        <mesh filename="package://moveit_resources_panda_description/meshes/visual/link5.dae"/>
      </geometry>
    </visual>
    <collision>
      <geometry>
        <mesh filename="package://moveit_resources_panda_description/meshes/collision/link5.stl"/>
      </geometry>
    </collision>
  </link>

  <joint name="panda_joint5" type="revolute">
    <parent link="panda_link4"/>
    <child link="panda_link5"/>
    <origin xyz="-0.0825 0.384 0" rpy="-1.57079632679 0 0"/>
    <axis xyz="0 0 1"/>
    <limit effort="12" lower="-2.9671" upper="2.9671" velocity="2.8710"/>
  </joint>

  <link name="panda_link6">
    <inertial>
      <mass value="1.0"/>
      <inertia ixx="0.005" ixy="0.0" ixz="0.0" iyy="0.005" iyz="0.0" izz="0.005"/>
    </inertial>
    <visual>
      <geometry>
        <mesh filename="package://moveit_resources_panda_description/meshes/visual/link6.dae"/>
      </geometry>
    </visual>
    <collision>
      <geometry>
        <mesh filename="package://moveit_resources_panda_description/meshes/collision/link6.stl"/>
      </geometry>
    </collision>
  </link>

  <joint name="panda_joint6" type="revolute">
    <parent link="panda_link5"/>
    <child link="panda_link6"/>
    <origin xyz="0 0 0" rpy="1.57079632679 0 0"/>
    <axis xyz="0 0 1"/>
    <limit effort="12" lower="-0.0873" upper="3.8223" velocity="2.8710"/>
  </joint>

  <link name="panda_link7">
    <inertial>
      <mass value="1.0"/>
      <inertia ixx="0.005" ixy="0.0" ixz="0.0" iyy="0.005" iyz="0.0" izz="0.005"/>
    </inertial>
    <visual>
      <geometry>
        <mesh filename="package://moveit_resources_panda_description/meshes/visual/link7.dae"/>
      </geometry>
    </visual>
    <collision>
      <geometry>
        <mesh filename="package://moveit_resources_panda_description/meshes/collision/link7.stl"/>
      </geometry>
    </collision>
  </link>

  <joint name="panda_joint7" type="revolute">
    <parent link="panda_link6"/>
    <child link="panda_link7"/>
    <origin xyz="0.088 0 0" rpy="1.57079632679 0 0"/>
    <axis xyz="0 0 1"/>
    <limit effort="12" lower="-2.9671" upper="2.9671" velocity="2.8710"/>
  </joint>

  <!-- 手爪 -->
  <link name="panda_hand">
    <inertial>
      <mass value="0.5"/>
      <inertia ixx="0.001" ixy="0.0" ixz="0.0" iyy="0.001" iyz="0.0" izz="0.001"/>
    </inertial>
    <visual>
      <geometry>
        <mesh filename="package://moveit_resources_panda_description/meshes/visual/hand.dae"/>
      </geometry>
    </visual>
    <collision>
      <geometry>
        <mesh filename="package://moveit_resources_panda_description/meshes/collision/hand.stl"/>
      </geometry>
    </collision>
  </link>

  <joint name="panda_hand_joint" type="fixed">
    <parent link="panda_link7"/>
    <child link="panda_hand"/>
    <origin xyz="0 0 0.107" rpy="0 0 -0.785398163397"/>
  </joint>

  <!-- 手指 -->
  <link name="panda_leftfinger">
    <inertial>
      <mass value="0.1"/>
      <inertia ixx="0.0001" ixy="0.0" ixz="0.0" iyy="0.0001" iyz="0.0" izz="0.0001"/>
    </inertial>
    <visual>
      <geometry>
        <mesh filename="package://moveit_resources_panda_description/meshes/visual/finger.dae"/>
      </geometry>
    </visual>
    <collision>
      <geometry>
        <mesh filename="package://moveit_resources_panda_description/meshes/collision/finger.stl"/>
      </geometry>
    </collision>
  </link>

  <link name="panda_rightfinger">
    <inertial>
      <mass value="0.1"/>
      <inertia ixx="0.0001" ixy="0.0" ixz="0.0" iyy="0.0001" iyz="0.0" izz="0.0001"/>
    </inertial>
    <visual>
      <origin xyz="0 0 0" rpy="0 0 3.14159265359"/>
      <geometry>
        <mesh filename="package://moveit_resources_panda_description/meshes/visual/finger.dae"/>
      </geometry>
    </visual>
    <collision>
      <origin xyz="0 0 0" rpy="0 0 3.14159265359"/>
      <geometry>
        <mesh filename="package://moveit_resources_panda_description/meshes/collision/finger.stl"/>
      </geometry>
    </collision>
  </link>

  <joint name="panda_finger_joint1" type="prismatic">
    <parent link="panda_hand"/>
    <child link="panda_leftfinger"/>
    <origin xyz="0 0 0.0584" rpy="0 0 0"/>
    <axis xyz="0 1 0"/>
    <limit effort="20" lower="0.0" upper="0.04" velocity="0.2"/>
  </joint>

  <joint name="panda_finger_joint2" type="prismatic">
    <parent link="panda_hand"/>
    <child link="panda_rightfinger"/>
    <origin xyz="0 0 0.0584" rpy="0 0 0"/>
    <axis xyz="0 -1 0"/>
    <limit effort="20" lower="0.0" upper="0.04" velocity="0.2"/>
  </joint>

  <!-- ========================== -->
  <!--      ROS2 Control 配置      -->
  <!-- ========================== -->
  <ros2_control name="panda_arm" type="system">
    <hardware>
      <plugin>gz_ros2_control/GazeboSystem</plugin>
      <param name="update_rate">1000</param>
    </hardware>
    
    <!-- 手臂关节 - 添加PID增益 -->
    <joint name="panda_joint1">
      <command_interface name="position">
        <param name="min">-2.9671</param>
        <param name="max">2.9671</param>
      </command_interface>
      <command_interface name="effort"/>
      <state_interface name="position"/>
      <state_interface name="velocity"/>
      <state_interface name="effort"/>
      <param name="p">2000</param>
      <param name="i">0</param>
      <param name="d">200</param>
    </joint>
    
    <joint name="panda_joint2">
      <command_interface name="position">
        <param name="min">-1.8326</param>
        <param name="max">1.8326</param>
      </command_interface>
      <command_interface name="effort"/>
      <state_interface name="position"/>
      <state_interface name="velocity"/>
      <state_interface name="effort"/>
      <param name="p">3000</param>
      <param name="i">0</param>
      <param name="d">200</param>
    </joint>
    
    <joint name="panda_joint3">
      <command_interface name="position">
        <param name="min">-2.9671</param>
        <param name="max">2.9671</param>
      </command_interface>
      <command_interface name="effort"/>
      <state_interface name="position"/>
      <state_interface name="velocity"/>
      <state_interface name="effort"/>
      <param name="p">2000</param>
      <param name="i">0</param>
      <param name="d">100</param>
    </joint>
    
    <joint name="panda_joint4">
      <command_interface name="position">
        <param name="min">-3.1416</param>
        <param name="max">0.0873</param>
      </command_interface>
      <command_interface name="effort"/>
      <state_interface name="position"/>
      <state_interface name="velocity"/>
      <state_interface name="effort"/>
      <param name="p">1000</param>
      <param name="i">0</param>
      <param name="d">10</param>
    </joint>
    
    <joint name="panda_joint5">
      <command_interface name="position">
        <param name="min">-2.9671</param>
        <param name="max">2.9671</param>
      </command_interface>
      <command_interface name="effort"/>
      <state_interface name="position"/>
      <state_interface name="velocity"/>
      <state_interface name="effort"/>
      <param name="p">2000</param>
      <param name="i">0</param>
      <param name="d">100</param>
    </joint>
    
    <joint name="panda_joint6">
      <command_interface name="position">
        <param name="min">-0.0873</param>
        <param name="max">3.8223</param>
      </command_interface>
      <command_interface name="effort"/>
      <state_interface name="position"/>
      <state_interface name="velocity"/>
      <state_interface name="effort"/>
      <param name="p">2000</param>
      <param name="i">0</param>
      <param name="d">100</param>
    </joint>
    
    <joint name="panda_joint7">
      <command_interface name="position">
        <param name="min">-2.9671</param>
        <param name="max">2.9671</param>
      </command_interface>
      <command_interface name="effort"/>
      <state_interface name="position"/>
      <state_interface name="velocity"/>
      <state_interface name="effort"/>
      <param name="p">2000</param>
      <param name="i">0</param>
      <param name="d">100</param>
    </joint>
    
    <!-- 夹爪关节 -->
    <joint name="panda_finger_joint1">
      <command_interface name="position">
        <param name="min">0.0</param>
        <param name="max">0.04</param>
      </command_interface>
      <state_interface name="position"/>
      <state_interface name="velocity"/>
      <state_interface name="effort"/>
      <param name="p">2000</param>
      <param name="i">0</param>
      <param name="d">100</param>
    </joint>
    
    <joint name="panda_finger_joint2">
      <command_interface name="position">
        <param name="min">0.0</param>
        <param name="max">0.04</param>
      </command_interface>
      <state_interface name="position"/>
      <state_interface name="velocity"/>
      <state_interface name="effort"/>
      <param name="p">2000</param>
      <param name="i">0</param>
      <param name="d">100</param>
    </joint>
  </ros2_control>

  <!-- ========================== -->
  <!--        Gazebo 插件         -->
  <!-- ========================== -->
  <gazebo>
    <plugin filename="libgz-sim-joint-trajectory-controller-system.so" name="joint_trajectory_controller">
      <joint_names>panda_joint1,panda_joint2,panda_joint3,panda_joint4,panda_joint5,panda_joint6,panda_joint7</joint_names>
      <initial_position>0,-0.785,0,-2.356,0,1.571,0.785</initial_position>
    </plugin>
  </gazebo>

  <!-- 添加物理引擎配置 -->
  <gazebo>
    <plugin filename="libgz-sim-physics-system.so" name="gz::sim::systems::Physics">
      <engine>bullet</engine>
      <max_step_size>0.001</max_step_size>
      <real_time_factor>1.0</real_time_factor>
    </plugin>
  </gazebo>

  <!-- 添加重力补偿插件 -->
  <gazebo>
    <plugin filename="libgz-sim-gravity-compensation-system.so" name="gz::sim::systems::GravityCompensation">
      <link_name>panda_link1</link_name>
      <link_name>panda_link2</link_name>
      <link_name>panda_link3</link_name>
      <link_name>panda_link4</link_name>
      <link_name>panda_link5</link_name>
      <link_name>panda_link6</link_name>
      <link_name>panda_link7</link_name>
    </plugin>
  </gazebo>

  <!-- ========================== -->
  <!--        ROS2 传输配置        -->
  <!-- ========================== -->
  <transmission name="panda_joint1_trans">
    <type>transmission_interface/SimpleTransmission</type>
    <joint name="panda_joint1">
      <hardwareInterface>hardware_interface/PositionJointInterface</hardwareInterface>
    </joint>
    <actuator name="panda_joint1_motor">
      <hardwareInterface>hardware_interface/PositionJointInterface</hardwareInterface>
      <mechanicalReduction>1</mechanicalReduction>
    </actuator>
  </transmission>

  <transmission name="panda_joint2_trans">
    <type>transmission_interface/SimpleTransmission</type>
    <joint name="panda_joint2">
      <hardwareInterface>hardware_interface/PositionJointInterface</hardwareInterface>
    </joint>
    <actuator name="panda_joint2_motor">
      <hardwareInterface>hardware_interface/PositionJointInterface</hardwareInterface>
      <mechanicalReduction>1</mechanicalReduction>
    </actuator>
  </transmission>

  <transmission name="panda_joint3_trans">
    <type>transmission_interface/SimpleTransmission</type>
    <joint name="panda_joint3">
      <hardwareInterface>hardware_interface/PositionJointInterface</hardwareInterface>
    </joint>
    <actuator name="panda_joint3_motor">
      <hardwareInterface>hardware_interface/PositionJointInterface</hardwareInterface>
      <mechanicalReduction>1</mechanicalReduction>
    </actuator>
  </transmission>

  <transmission name="panda_joint4_trans">
    <type>transmission_interface/SimpleTransmission</type>
    <joint name="panda_joint4">
      <hardwareInterface>hardware_interface/PositionJointInterface</hardwareInterface>
    </joint>
    <actuator name="panda_joint4_motor">
      <hardwareInterface>hardware_interface/PositionJointInterface</hardwareInterface>
      <mechanicalReduction>1</mechanicalReduction>
    </actuator>
  </transmission>

  <transmission name="panda_joint5_trans">
    <type>transmission_interface/SimpleTransmission</type>
    <joint name="panda_joint5">
      <hardwareInterface>hardware_interface/PositionJointInterface</hardwareInterface>
    </joint>
    <actuator name="panda_joint5_motor">
      <hardwareInterface>hardware_interface/PositionJointInterface</hardwareInterface>
      <mechanicalReduction>1</mechanicalReduction>
    </actuator>
  </transmission>

  <transmission name="panda_joint6_trans">
    <type>transmission_interface/SimpleTransmission</type>
    <joint name="panda_joint6">
      <hardwareInterface>hardware_interface/PositionJointInterface</hardwareInterface>
    </joint>
    <actuator name="panda_joint6_motor">
      <hardwareInterface>hardware_interface/PositionJointInterface</hardwareInterface>
      <mechanicalReduction>1</mechanicalReduction>
    </actuator>
  </transmission>

  <transmission name="panda_joint7_trans">
    <type>transmission_interface/SimpleTransmission</type>
    <joint name="panda_joint7">
      <hardwareInterface>hardware_interface/PositionJointInterface</hardwareInterface>
    </joint>
    <actuator name="panda_joint7_motor">
      <hardwareInterface>hardware_interface/PositionJointInterface</hardwareInterface>
      <mechanicalReduction>1</mechanicalReduction>
    </actuator>
  </transmission>

  <transmission name="panda_finger_joint1_trans">
    <type>transmission_interface/SimpleTransmission</type>
    <joint name="panda_finger_joint1">
      <hardwareInterface>hardware_interface/PositionJointInterface</hardwareInterface>
    </joint>
    <actuator name="panda_finger_joint1_motor">
      <hardwareInterface>hardware_interface/PositionJointInterface</hardwareInterface>
      <mechanicalReduction>1</mechanicalReduction>
    </actuator>
  </transmission>

  <transmission name="panda_finger_joint2_trans">
    <type>transmission_interface/SimpleTransmission</type>
    <joint name="panda_finger_joint2">
      <hardwareInterface>hardware_interface/PositionJointInterface</hardwareInterface>
    </joint>
    <actuator name="panda_finger_joint2_motor">
      <hardwareInterface>hardware_interface/PositionJointInterface</hardwareInterface>
      <mechanicalReduction>1</mechanicalReduction>
    </actuator>
  </transmission>

  <!-- ========================== -->
  <!--      Gazebo 材料属性       -->
  <!-- ========================== -->
  <gazebo reference="panda_link0">
    <material>Gazebo/Grey</material>
    <kp>1000000.0</kp>
    <kd>100.0</kd>
  </gazebo>
  
  <gazebo reference="panda_link1">
    <material>Gazebo/Orange</material>
    <kp>1000000.0</kp>
    <kd>100.0</kd>
  </gazebo>
  
  <gazebo reference="panda_link2">
    <material>Gazebo/Grey</material>
    <kp>1000000.0</kp>
    <kd>100.0</kd>
  </gazebo>
  
  <gazebo reference="panda_link3">
    <material>Gazebo/Orange</material>
    <kp>1000000.0</kp>
    <kd>100.0</kd>
  </gazebo>
  
  <gazebo reference="panda_link4">
    <material>Gazebo/Grey</material>
    <kp>1000000.0</kp>
    <kd>100.0</kd>
  </gazebo>
  
  <gazebo reference="panda_link5">
    <material>Gazebo/Orange</material>
    <kp>1000000.0</kp>
    <kd>100.0</kd>
  </gazebo>
  
  <gazebo reference="panda_link6">
    <material>Gazebo/Grey</material>
    <kp>1000000.0</kp>
    <kd>100.0</kd>
  </gazebo>
  
  <gazebo reference="panda_link7">
    <material>Gazebo/Orange</material>
    <kp>1000000.0</kp>
    <kd>100.0</kd>
  </gazebo>
  
  <gazebo reference="panda_hand">
    <material>Gazebo/Black</material>
    <kp>1000000.0</kp>
    <kd>100.0</kd>
  </gazebo>
  
  <gazebo reference="panda_leftfinger">
    <material>Gazebo/White</material>
    <kp>1000000.0</kp>
    <kd>100.0</kd>
  </gazebo>
  
  <gazebo reference="panda_rightfinger">
    <material>Gazebo/White</material>
    <kp>1000000.0</kp>
    <kd>100.0</kd>
  </gazebo>

</robot>